Workbook

Sheet Productos
A1: id | B1: slug | C1: sku | D1: marca | E1: nombre_original_pt | F1: nombre_es | G1: linea | H1: categoria_original_pt | I1: categoria_es | J1: subcategoria_original_pt | K1: subcategoria_es | L1: tipo_original_pt | M1: tipo_es | N1: presentacion | O1: cantidad | P1: unidad | Q1: precio_regular_brl | R1: precio_oferta_brl | S1: porcentaje_descuento | T1: en_oferta | U1: disponible | V1: descripcion_original_pt | W1: descripcion_es | X1: beneficios_original_pt | Y1: beneficios_es | Z1: propiedades_original_pt | AA1: propiedades_es | AB1: modo_uso_original_pt | AC1: modo_uso_es | AD1: activos_original_pt | AE1: activos_es | AF1: ingredientes_originales | AG1: imagen_principal_url | AH1: imagen_principal_local | AI1: imagenes_adicionales | AJ1: recomendado_para_es | AK1: url_origen | AL1: fecha_extraccion | AM1: precio_regular_pen | AN1: pvp_peru_regular_pen | AO1: precio_oferta_pen | AP1: pvp_peru_oferta_pen
A2: HSK-0001 | B2: tonico-activador-cavalo-forte-120-ml | D2: Haskell | E2: Tonico Ativador Cavalo Forte 120ml | F2: Tonico activador Cavalo Forte 120 ml | G2: Cavalo Forte | H2: Tratamentos Capilares | I2: Tratamientos capilares | J2: Fortalecimento | K2: Fortalecimiento capilar | L2: Tonico | M2: Tonico capilar | N2: 120 ml | O2: 120 | P2: ml | Q2: 56.9 | S2: =IF(ISBLANK(R2),0,IFERROR((Q2-R2)/Q2,0)) | T2: =R2<>"" | U2: =TRUE() | W2: Tonico capilar de la linea Cavalo Forte, formulado para estimular el cuero cabelludo y acompanar el crecimiento saludable del cabello, como parte de una rutina de fortalecimiento. | Y2: Estimula el cuero cabelludo | Contribuye al crecimiento capilar saludable | Fortalece la raiz del cabello | AA2: Fortalecedor | Estimulante del cuero cabelludo | AC2: Aplicar directamente sobre el cuero cabelludo limpio y masajear suavemente. No es necesario enjuagar. | AD2: Biotina | Pantenol | Queratina | AE2: Biotina | Pantenol | Queratina | AH2: tonico-ativador-cavalo-forte-120ml.webp | AJ2: Todo tipo de cabello, especialmente cabello debilitado o con caida | AK2: https://haskellcosmeticos.com.br/tratamentos-capilares/linha-cavalo-forte-haskell/ | AL2: 2026-07-24 | AM2: =IF(ISBLANK(Q2),"",Q2*Parametros_PEN!$B$2) | AN2: =IF(ISBLANK(Q2),"",Q2*Parametros_PEN!$B$2*(1+Parametros_PEN!$B$3)) | AO2: =IF(ISBLANK(R2),"",R2*Parametros_PEN!$B$2) | AP2: =IF(ISBLANK(R2),"",R2*Parametros_PEN!$B$2*(1+Parametros_PEN!$B$3))
A3: HSK-0002 | B3: champu-bendito-loiro-300-ml | D3: Haskell | E3: Shampoo Bendito Loiro 300ml | F3: Champu Bendito Loiro 300 ml | G3: Bendito Loiro | H3: Tratamentos Capilares | I3: Tratamientos capilares | J3: Cabelos descoloridos | K3: Cabello decolorado | L3: Shampoo | M3: Champu | N3: 300 ml | O3: 300 | P3: ml | Q3: 62.9 | S3: =IF(ISBLANK(R3),0,IFERROR((Q3-R3)/Q3,0)) | T3: =R3<>"" | U3: =TRUE() | W3: Champu de limpieza suave de la linea Bendito Loiro, formulado para preparar el cabello decolorado antes del tratamiento, sin agredir la fibra capilar y manteniendo el pH equilibrado. | Y3: Limpieza suave sin agredir los cabellos | Mantiene el pH equilibrado | Evita la rigidez del cabello | AA3: Limpiador suave | pH equilibrado | AC3: Aplicar sobre el cabello mojado, masajear el cuero cabelludo y enjuagar bien. | AD3: Complexo de proteinas | Vinagre balsamico de uva | AE3: Complejo de proteinas | Vinagre balsamico de uva | AH3: shampoo-bendito-loiro-300ml.webp | AJ3: Cabello decolorado o rubio con danos, elasticidad excesiva o porosidad | AK3: https://haskellcosmeticos.com.br/tratamentos-capilares/bendito-loiro/ | AL3: 2026-07-24 | AM3: =IF(ISBLANK(Q3),"",Q3*Parametros_PEN!$B$2) | AN3: =IF(ISBLANK(Q3),"",Q3*Parametros_PEN!$B$2*(1+Parametros_PEN!$B$3)) | AO3: =IF(ISBLANK(R3),"",R3*Parametros_PEN!$B$2) | AP3: =IF(ISBLANK(R3),"",R3*Parametros_PEN!$B$2*(1+Parametros_PEN!$B$3))
A4: HSK-0003 | B4: champu-bendito-loiro-500-ml | D4: Haskell | E4: Shampoo Bendito Loiro 500ml | F4: Champu Bendito Loiro 500 ml | G4: Bendito Loiro | H4: Tratamentos Capilares | I4: Tratamientos capilares | J4: Cabelos descoloridos | K4: Cabello decolorado | L4: Shampoo | M4: Champu | N4: 500 ml | O4: 500 | P4: ml | Q4: 84.9 | S4: =IF(ISBLANK(R4),0,IFERROR((Q4-R4)/Q4,0)) | T4: =R4<>"" | U4: =TRUE() | W4: Champu de limpieza suave de la linea Bendito Loiro, formulado para preparar el cabello decolorado antes del tratamiento, sin agredir la fibra capilar y manteniendo el pH equilibrado. | Y4: Limpieza suave sin agredir los cabellos | Mantiene el pH equilibrado | Evita la rigidez del cabello | AA4: Limpiador suave | pH equilibrado | AC4: Aplicar sobre el cabello mojado, masajear el cuero cabelludo y enjuagar bien. | AD4: Complexo de proteinas | Vinagre balsamico de uva | AE4: Complejo de proteinas | Vinagre balsamico de uva | AH4: shampoo-bendito-loiro-500ml.webp | AJ4: Cabello decolorado o rubio con danos, elasticidad excesiva o porosidad | AK4: https://haskellcosmeticos.com.br/tratamentos-capilares/bendito-loiro/ | AL4: 2026-07-24 | AM4: =IF(ISBLANK(Q4),"",Q4*Parametros_PEN!$B$2) | AN4: =IF(ISBLANK(Q4),"",Q4*Parametros_PEN!$B$2*(1+Parametros_PEN!$B$3)) | AO4: =IF(ISBLANK(R4),"",R4*Parametros_PEN!$B$2) | AP4: =IF(ISBLANK(R4),"",R4*Parametros_PEN!$B$2*(1+Parametros_PEN!$B$3))
A5: HSK-0004 | B5: acondicionador-bendito-loiro-300-ml | D5: Haskell | E5: Condicionador Bendito Loiro 300ml | F5: Acondicionador Bendito Loiro 300 ml | G5: Bendito Loiro | H5: Tratamentos Capilares | I5: Tratamientos capilares | J5: Cabelos descoloridos | K5: Cabello decolorado | L5: Condicionador | M5: Acondicionador | N5: 300 ml | O5: 300 | P5: ml | Q5: 62.9 | S5: =IF(ISBLANK(R5),0,IFERROR((Q5-R5)/Q5,0)) | T5: =R5<>"" | U5: =TRUE() | W5: Acondicionador de la linea Bendito Loiro que sella las cuticulas, repone proteinas y reduce la electricidad estatica del cabello decolorado, aportando suavidad y liviandad. | Y5: Sella las cuticulas | Reduce la electricidad estatica | Repone proteinas | Aporta suavidad y liviandad | AA5: Sellador de cuticulas | Reposicion de proteinas | AC5: Aplicar sobre el cabello lavado, de medios a puntas, dejar actuar unos minutos y enjuagar. | AD5: Complexo de proteinas | Vinagre balsamico de uva | AE5: Complejo de proteinas | Vinagre balsamico de uva | AH5: condicionador-bendito-loiro-300ml.webp | AJ5: Cabello decolorado o rubio con danos, elasticidad excesiva o porosidad | AK5: https://haskellcosmeticos.com.br/tratamentos-capilares/bendito-loiro/ | AL5: 2026-07-24 | AM5: =IF(ISBLANK(Q5),"",Q5*Parametros_PEN!$B$2) | AN5: =IF(ISBLANK(Q5),"",Q5*Parametros_PEN!$B$2*(1+Parametros_PEN!$B$3)) | AO5: =IF(ISBLANK(R5),"",R5*Parametros_PEN!$B$2) | AP5: =IF(ISBLANK(R5),"",R5*Parametros_PEN!$B$2*(1+Parametros_PEN!$B$3))
A6: HSK-0005 | B6: mascarilla-de-tratamiento-bendito-loiro-300-g | D6: Haskell | E6: Mascara de Tratamento Bendito Loiro 300g | F6: Mascarilla de tratamiento Bendito Loiro 300 g | G6: Bendito Loiro | H6: Tratamentos Capilares | I6: Tratamientos capilares | J6: Cabelos descoloridos | K6: Cabello decolorado | L6: Mascara de Tratamento | M6: Mascarilla de tratamiento | N6: 300 g | O6: 300 | P6: g | Q6: 74.9 | S6: =IF(ISBLANK(R6),0,IFERROR((Q6-R6)/Q6,0)) | T6: =R6<>"" | U6: =TRUE() | W6: Mascarilla de alto poder reconstructor de la linea Bendito Loiro, indicada para el tratamiento profundo y la regeneracion de los danos causados por la decoloracion. | Y6: Alto poder reconstructor | Tratamiento profundo | Regenera danos de la decoloracion | AA6: Reconstructora | Regeneradora | AC6: Aplicar sobre el cabello lavado, distribuir de medios a puntas y dejar actuar segun las indicaciones del envase antes de enjuagar. | AD6: Complexo de proteinas | Vinagre balsamico de uva | AE6: Complejo de proteinas | Vinagre balsamico de uva | AH6: mascara-de-tratamento-bendito-loiro-300g.webp | AJ6: Cabello decolorado o rubio con danos, elasticidad excesiva o porosidad | AK6: https://haskellcosmeticos.com.br/tratamentos-capilares/bendito-loiro/ | AL6: 2026-07-24 | AM6: =IF(ISBLANK(Q6),"",Q6*Parametros_PEN!$B$2) | AN6: =IF(ISBLANK(Q6),"",Q6*Parametros_PEN!$B$2*(1+Parametros_PEN!$B$3)) | AO6: =IF(ISBLANK(R6),"",R6*Parametros_PEN!$B$2) | AP6: =IF(ISBLANK(R6),"",R6*Parametros_PEN!$B$2*(1+Parametros_PEN!$B$3))
A7: HSK-0006 | B7: proteina-capilar-bendito-loiro-150-g | D7: Haskell | E7: Proteina Capilar Bendito Loiro 150g | F7: Proteina capilar Bendito Loiro 150 g | G7: Bendito Loiro | H7: Tratamentos Capilares | I7: Tratamientos capilares | J7: Cabelos descoloridos | K7: Cabello decolorado | L7: Reparador | M7: Proteina capilar | N7: 150 g | O7: 150 | P7: g | Q7: 55.9 | S7: =IF(ISBLANK(R7),0,IFERROR((Q7-R7)/Q7,0)) | T7: =R7<>"" | U7: =TRUE() | W7: Pre-champu repositor inmediato de proteina de la linea Bendito Loiro, que reconstruye la estructura interna del cabello y reduce el riesgo de quiebre. | Y7: Reconstruye la estructura interna del cabello | Reduce el riesgo de quiebre | Actua contra la elasticidad excesiva | AA7: Repositor de proteina | Pre-tratamiento | AC7: Aplicar antes del champu, sobre el cabello seco o humedo, siguiendo las indicaciones del envase. | AD7: Complexo de proteinas | AE7: Complejo de proteinas | AH7: proteina-capilar-bendito-loiro-150g.webp | AJ7: Cabello decolorado o rubio con danos, elasticidad excesiva o porosidad | AK7: https://haskellcosmeticos.com.br/tratamentos-capilares/bendito-loiro/ | AL7: 2026-07-24 | AM7: =IF(ISBLANK(Q7),"",Q7*Parametros_PEN!$B$2) | AN7: =IF(ISBLANK(Q7),"",Q7*Parametros_PEN!$B$2*(1+Parametros_PEN!$B$3)) | AO7: =IF(ISBLANK(R7),"",R7*Parametros_PEN!$B$2) | AP7: =IF(ISBLANK(R7),"",R7*Parametros_PEN!$B$2*(1+Parametros_PEN!$B$3))
A8: HSK-0007 | B8: fluido-proteico-bendito-loiro-120-ml | D8: Haskell | E8: Fluido Proteico Bendito Loiro 120ml | F8: Fluido proteico Bendito Loiro 120 ml | G8: Bendito Loiro | H8: Tratamentos Capilares | I8: Tratamientos capilares | J8: Cabelos descoloridos | K8: Cabello decolorado | L8: Finalizador | M8: Fluido finalizador | N8: 120 ml | O8: 120 | P8: ml | Q8: 48.9 | S8: =IF(ISBLANK(R8),0,IFERROR((Q8-R8)/Q8,0)) | T8: =R8<>"" | U8: =TRUE() | W8: Fluido finalizador de la linea Bendito Loiro que aporta luminosidad, accion antifrizz y proteccion termica y solar al cabello decolorado. | Y8: Aporta luminosidad | Accion antifrizz | Proteccion termica y solar | AA8: Finalizador | Protector termico | AC8: Aplicar una pequena cantidad sobre el cabello humedo o seco, de medios a puntas, antes de peinar o usar herramientas de calor. | AD8: Complexo de proteinas | Vinagre balsamico de uva | AE8: Complejo de proteinas | Vinagre balsamico de uva | AH8: fluido-proteico-bendito-loiro-120ml.webp | AJ8: Cabello decolorado o rubio con danos, elasticidad excesiva o porosidad | AK8: https://haskellcosmeticos.com.br/tratamentos-capilares/bendito-loiro/ | AL8: 2026-07-24 | AM8: =IF(ISBLANK(Q8),"",Q8*Parametros_PEN!$B$2) | AN8: =IF(ISBLANK(Q8),"",Q8*Parametros_PEN!$B$2*(1+Parametros_PEN!$B$3)) | AO8: =IF(ISBLANK(R8),"",R8*Parametros_PEN!$B$2) | AP8: =IF(ISBLANK(R8),"",R8*Parametros_PEN!$B$2*(1+Parametros_PEN!$B$3))
A9: HSK-0008 | B9: champu-de-uso-diario-matcha-y-romero-300-ml | D9: Haskell | E9: Shampoo Uso Diario Matcha & Alecrim 300ml | F9: Champu de uso diario Matcha y romero 300 ml | G9: Matcha | H9: Tratamentos Capilares | I9: Tratamientos capilares | J9: Controle da oleosidade | K9: Control de la grasitud capilar | L9: Shampoo | M9: Champu | N9: 300 ml | O9: 300 | P9: ml | Q9: 58.9 | S9: =IF(ISBLANK(R9),0,IFERROR((Q9-R9)/Q9,0)) | T9: =R9<>"" | U9: =TRUE() | W9: Champu de uso diario de la linea Matcha, formulado con matcha y romero para controlar la grasitud del cuero cabelludo y mantener el cabello limpio y liviano por mas tiempo. | Y9: Controla la grasitud del cuero cabelludo | Fortalece los cabellos desde la raiz | Mantiene la limpieza por mas tiempo | AA9: Anti-grasitud | Limpieza diaria | AC9: Aplicar sobre el cabello mojado, masajear el cuero cabelludo y enjuagar. Puede usarse a diario. | AD9: Matcha | Extrato de Alecrim | AE9: Matcha | Extracto de romero | AH9: shampoo-uso-diario-matcha-alecrim-300ml.webp | AJ9: Cabello graso o con tendencia a la grasitud excesiva | AK9: https://haskellcosmeticos.com.br/tratamentos-capilares/linha-matcha-haskell/ | AL9: 2026-07-24 | AM9: =IF(ISBLANK(Q9),"",Q9*Parametros_PEN!$B$2) | AN9: =IF(ISBLANK(Q9),"",Q9*Parametros_PEN!$B$2*(1+Parametros_PEN!$B$3)) | AO9: =IF(ISBLANK(R9),"",R9*Parametros_PEN!$B$2) | AP9: =IF(ISBLANK(R9),"",R9*Parametros_PEN!$B$2*(1+Parametros_PEN!$B$3))
A10: HSK-0009 | B10: champu-antirresiduos-matcha-y-menta-300-ml | D10: Haskell | E10: Shampoo Antirresiduos Matcha & Hortela 300ml | F10: Champu antirresiduos Matcha y menta 300 ml | G10: Matcha | H10: Tratamentos Capilares | I10: Tratamientos capilares | J10: Controle da oleosidade | K10: Control de la grasitud capilar | L10: Shampoo | M10: Champu | N10: 300 ml | O10: 300 | P10: ml | Q10: 58.9 | S10: =IF(ISBLANK(R10),0,IFERROR((Q10-R10)/Q10,0)) | T10: =R10<>"" | U10: =TRUE() | W10: Champu de limpieza profunda de la linea Matcha, formulado con matcha y menta para eliminar residuos de productos de peinado y contaminacion, y prevenir la caida del cabello. | Y10: Limpieza profunda | Elimina residuos de productos y contaminacion | Previene la caida del cabello | Sensacion de frescor | AA10: Limpieza profunda | Efecto refrescante | AC10: Aplicar sobre el cabello mojado, masajear el cuero cabelludo y enjuagar bien. Se recomienda su uso periodico, no necesariamente a diario. | AD10: Matcha | Extrato de Hortela | AE10: Matcha | Extracto de menta | AH10: shampoo-antirresiduos-matcha-hortela-300ml.webp | AJ10: Cabello graso o con acumulacion de residuos de productos | AK10: https://haskellcosmeticos.com.br/tratamentos-capilares/linha-matcha-haskell/ | AL10: 2026-07-24 | AM10: =IF(ISBLANK(Q10),"",Q10*Parametros_PEN!$B$2) | AN10: =IF(ISBLANK(Q10),"",Q10*Parametros_PEN!$B$2*(1+Parametros_PEN!$B$3)) | AO10: =IF(ISBLANK(R10),"",R10*Parametros_PEN!$B$2) | AP10: =IF(ISBLANK(R10),"",R10*Parametros_PEN!$B$2*(1+Parametros_PEN!$B$3))
A11: HSK-0010 | B11: acondicionador-matcha-y-romero-300-ml | D11: Haskell | E11: Condicionador Matcha & Alecrim 300ml | F11: Acondicionador Matcha y romero 300 ml | G11: Matcha | H11: Tratamentos Capilares | I11: Tratamientos capilares | J11: Controle da oleosidade | K11: Control de la grasitud capilar | L11: Condicionador | M11: Acondicionador | N11: 300 ml | O11: 300 | P11: ml | Q11: 58.9 | S11: =IF(ISBLANK(R11),0,IFERROR((Q11-R11)/Q11,0)) | T11: =R11<>"" | U11: =TRUE() | W11: Acondicionador liviano de la linea Matcha que protege el cabello sin sobrecargarlo, ayuda a prevenir la caida y evita el resecamiento de las puntas. | Y11: Condiciona sin sobrecargar el cabello | Ayuda a prevenir la caida | Evita el resecamiento de las puntas | AA11: Liviano | No sobrecarga el cabello | AC11: Aplicar sobre el cabello lavado, de medios a puntas, dejar actuar y enjuagar. | AD11: Matcha | Extrato de Alecrim | AE11: Matcha | Extracto de romero | AH11: condicionador-matcha-alecrim-300ml.webp | AJ11: Cabello graso o con tendencia a la grasitud excesiva | AK11: https://haskellcosmeticos.com.br/tratamentos-capilares/linha-matcha-haskell/ | AL11: 2026-07-24 | AM11: =IF(ISBLANK(Q11),"",Q11*Parametros_PEN!$B$2) | AN11: =IF(ISBLANK(Q11),"",Q11*Parametros_PEN!$B$2*(1+Parametros_PEN!$B$3)) | AO11: =IF(ISBLANK(R11),"",R11*Parametros_PEN!$B$2) | AP11: =IF(ISBLANK(R11),"",R11*Parametros_PEN!$B$2*(1+Parametros_PEN!$B$3))
A12: HSK-0011 | B12: fluido-revitalizante-matcha-y-romero-120-ml | D12: Haskell | E12: Fluido Revitalizante Matcha & Alecrim 120ml | F12: Fluido revitalizante Matcha y romero 120 ml | G12: Matcha | H12: Tratamentos Capilares | I12: Tratamientos capilares | J12: Controle da oleosidade | K12: Control de la grasitud capilar | L12: Finalizador | M12: Fluido finalizador | N12: 120 ml | O12: 120 | P12: ml | Q12: 48.9 | S12: =IF(ISBLANK(R12),0,IFERROR((Q12-R12)/Q12,0)) | T12: =R12<>"" | U12: =TRUE() | W12: Fluido liviano y de rapida absorcion de la linea Matcha, que protege la fibra capilar frente a agresores externos y aporta luminosidad adicional. | Y12: Absorcion rapida | Protege la fibra capilar | Aporta luminosidad adicional | AA12: Liviano | Facil absorcion | AC12: Aplicar una pequena cantidad sobre el cabello humedo o seco, evitando la raiz si el cabello es graso. | AD12: Matcha | Extrato de Alecrim | AE12: Matcha | Extracto de romero | AH12: fluido-revitalizante-matcha-alecrim-120ml.webp | AJ12: Cabello graso o con tendencia a la grasitud excesiva | AK12: https://haskellcosmeticos.com.br/tratamentos-capilares/linha-matcha-haskell/ | AL12: 2026-07-24 | AM12: =IF(ISBLANK(Q12),"",Q12*Parametros_PEN!$B$2) | AN12: =IF(ISBLANK(Q12),"",Q12*Parametros_PEN!$B$2*(1+Parametros_PEN!$B$3)) | AO12: =IF(ISBLANK(R12),"",R12*Parametros_PEN!$B$2) | AP12: =IF(ISBLANK(R12),"",R12*Parametros_PEN!$B$2*(1+Parametros_PEN!$B$3))
A13: HSK-0012 | B13: champu-murumuru-300-ml | D13: Haskell | E13: Shampoo Murumuru 300ml | F13: Champu Murumuru 300 ml | G13: Murumuru | H13: Tratamentos Capilares | I13: Tratamientos capilares | J13: Nutricao intensa | K13: Nutricion intensa | L13: Shampoo | M13: Champu | N13: 300 ml | O13: 300 | P13: ml | Q13: 58.9 | S13: =IF(ISBLANK(R13),0,IFERROR((Q13-R13)/Q13,0)) | T13: =R13<>"" | U13: =TRUE() | W13: Champu de la linea Murumuru que realiza una limpieza suave y repone nutrientes y vitaminas esenciales, indicado para cabello muy seco. | Y13: Limpieza suave | Repone nutrientes y vitaminas esenciales | AA13: Nutritivo | Limpieza suave | AC13: Aplicar sobre el cabello mojado, masajear el cuero cabelludo y enjuagar bien. | AD13: Manteiga de Murumuru | AE13: Manteca de murumuru | AH13: shampoo-murumuru-300ml.webp | AJ13: Cabello muy seco, opaco o deshidratado | AK13: https://haskellcosmeticos.com.br/tratamentos-capilares/linha-murumuru-haskell/ | AL13: 2026-07-24 | AM13: =IF(ISBLANK(Q13),"",Q13*Parametros_PEN!$B$2) | AN13: =IF(ISBLANK(Q13),"",Q13*Parametros_PEN!$B$2*(1+Parametros_PEN!$B$3)) | AO13: =IF(ISBLANK(R13),"",R13*Parametros_PEN!$B$2) | AP13: =IF(ISBLANK(R13),"",R13*Parametros_PEN!$B$2*(1+Parametros_PEN!$B$3))
A14: HSK-0013 | B14: champu-murumuru-500-ml | D14: Haskell | E14: Shampoo Murumuru 500ml | F14: Champu Murumuru 500 ml | G14: Murumuru | H14: Tratamentos Capilares | I14: Tratamientos capilares | J14: Nutricao intensa | K14: Nutricion intensa | L14: Shampoo | M14: Champu | N14: 500 ml | O14: 500 | P14: ml | Q14: 76.9 | S14: =IF(ISBLANK(R14),0,IFERROR((Q14-R14)/Q14,0)) | T14: =R14<>"" | U14: =TRUE() | W14: Champu de la linea Murumuru que realiza una limpieza suave y repone nutrientes y vitaminas esenciales, indicado para cabello muy seco. | Y14: Limpieza suave | Repone nutrientes y vitaminas esenciales | AA14: Nutritivo | Limpieza suave | AC14: Aplicar sobre el cabello mojado, masajear el cuero cabelludo y enjuagar bien. | AD14: Manteiga de Murumuru | AE14: Manteca de murumuru | AH14: shampoo-murumuru-haskell-500ml.webp | AJ14: Cabello muy seco, opaco o deshidratado | AK14: https://haskellcosmeticos.com.br/tratamentos-capilares/linha-murumuru-haskell/ | AL14: 2026-07-24 | AM14: =IF(ISBLANK(Q14),"",Q14*Parametros_PEN!$B$2) | AN14: =IF(ISBLANK(Q14),"",Q14*Parametros_PEN!$B$2*(1+Parametros_PEN!$B$3)) | AO14: =IF(ISBLANK(R14),"",R14*Parametros_PEN!$B$2) | AP14: =IF(ISBLANK(R14),"",R14*Parametros_PEN!$B$2*(1+Parametros_PEN!$B$3))
A15: HSK-0014 | B15: fluido-alineador-frizz-cancelado-200-ml | D15: Haskell | E15: Fluido Alinhador Frizz Cancelado 200ml | F15: Fluido alineador Frizz Cancelado 200 ml | G15: Frizz Cancelado | H15: Tratamentos Capilares | I15: Tratamientos capilares | J15: Controle de frizz | K15: Control del frizz | L15: Finalizador | M15: Fluido finalizador | N15: 200 ml | O15: 200 | P15: ml | Q15: 59.9 | S15: =IF(ISBLANK(R15),0,IFERROR((Q15-R15)/Q15,0)) | T15: =R15<>"" | U15: =TRUE() | W15: Fluido finalizador de la linea Frizz Cancelado que ayuda a alinear y disciplinar el cabello, dejandolo con brillo intenso durante todo el dia sin apelmazarlo. | Y15: Alinea y disciplina el cabello | Brillo intenso durante todo el dia | No apelmaza el cabello | AA15: Alineador | Antifrizz | AC15: Aplicar sobre el cabello humedo o seco, de medios a puntas, antes de peinar. | AE15: No especificado en la pagina de linea (pendiente de confirmar en ficha de producto) | AH15: fluido-alinhador-frizz-cancelado-200ml.webp | AI15: fluido-alinhador-frizz-cancelado-200ml_02.webp | AJ15: Cabello con frizz | AK15: https://haskellcosmeticos.com.br/tratamentos-capilares/frizz-cancelado/ | AL15: 2026-07-24 | AM15: =IF(ISBLANK(Q15),"",Q15*Parametros_PEN!$B$2) | AN15: =IF(ISBLANK(Q15),"",Q15*Parametros_PEN!$B$2*(1+Parametros_PEN!$B$3)) | AO15: =IF(ISBLANK(R15),"",R15*Parametros_PEN!$B$2) | AP15: =IF(ISBLANK(R15),"",R15*Parametros_PEN!$B$2*(1+Parametros_PEN!$B$3))
A16: HSK-0015 | B16: aceite-blindaje-capilar-frizz-cancelado-100-ml | D16: Haskell | E16: Oleo Blinda Fio Frizz Cancelado 100ml | F16: Aceite blindaje capilar Frizz Cancelado 100 ml | G16: Frizz Cancelado | H16: Tratamentos Capilares | I16: Tratamientos capilares | J16: Controle de frizz | K16: Control del frizz | L16: Reparador | M16: Aceite capilar | N16: 100 ml | O16: 100 | P16: ml | Q16: 95.9 | S16: =IF(ISBLANK(R16),0,IFERROR((Q16-R16)/Q16,0)) | T16: =R16<>"" | U16: =TRUE() | W16: Aceite capilar de la linea Frizz Cancelado, formulado para proteger la fibra capilar y contribuir al control del frizz, dejando el cabello con brillo. | Y16: Protege la fibra capilar | Contribuye al control del frizz | Aporta brillo | AA16: Protector | Antifrizz | AC16: Aplicar pocas gotas sobre el cabello humedo o seco, de medios a puntas. | AE16: No especificado en la pagina de linea (pendiente de confirmar en ficha de producto) | AH16: oleo-blinda-fio-frizz-cancelado-100ml.webp | AI16: oleo-blinda-fio-frizz-cancelado-100ml_02.webp | AJ16: Cabello con frizz | AK16: https://haskellcosmeticos.com.br/tratamentos-capilares/frizz-cancelado/ | AL16: 2026-07-24 | AM16: =IF(ISBLANK(Q16),"",Q16*Parametros_PEN!$B$2) | AN16: =IF(ISBLANK(Q16),"",Q16*Parametros_PEN!$B$2*(1+Parametros_PEN!$B$3)) | AO16: =IF(ISBLANK(R16),"",R16*Parametros_PEN!$B$2) | AP16: =IF(ISBLANK(R16),"",R16*Parametros_PEN!$B$2*(1+Parametros_PEN!$B$3))
A17: HSK-0016 | B17: mascarilla-liquida-lamelar-frizz-cancelado-200-ml | D17: Haskell | E17: Mascara Liquida Lamelar Frizz Cancelado 200ml | F17: Mascarilla liquida lamelar Frizz Cancelado 200 ml | G17: Frizz Cancelado | H17: Tratamentos Capilares | I17: Tratamientos capilares | J17: Controle de frizz | K17: Control del frizz | L17: Mascara Liquida Lamelar | M17: Mascarilla liquida lamelar | N17: 200 ml | O17: 200 | P17: ml | Q17: 81.9 | S17: =IF(ISBLANK(R17),0,IFERROR((Q17-R17)/Q17,0)) | T17: =R17<>"" | U17: =TRUE() | W17: Mascarilla liquida de tecnologia lamelar de la linea Frizz Cancelado, que ayuda a alinear el cabello y controlar el frizz con un acabado liviano. | Y17: Alinea el cabello | Controla el frizz | Acabado liviano | AA17: Tecnologia lamelar | Antifrizz | AC17: Aplicar sobre el cabello lavado, distribuir de medios a puntas y enjuagar segun las indicaciones del envase. | AE17: No especificado en la pagina de linea (pendiente de confirmar en ficha de producto) | AH17: mascara-liquida-lamelar-frizz-cancelado-200ml.webp | AI17: mascara-liquida-lamelar-frizz-cancelado-200ml_02.webp | AJ17: Cabello con frizz | AK17: https://haskellcosmeticos.com.br/tratamentos-capilares/frizz-cancelado/ | AL17: 2026-07-24 | AM17: =IF(ISBLANK(Q17),"",Q17*Parametros_PEN!$B$2) | AN17: =IF(ISBLANK(Q17),"",Q17*Parametros_PEN!$B$2*(1+Parametros_PEN!$B$3)) | AO17: =IF(ISBLANK(R17),"",R17*Parametros_PEN!$B$2) | AP17: =IF(ISBLANK(R17),"",R17*Parametros_PEN!$B$2*(1+Parametros_PEN!$B$3))
A18: HSK-0017 | B18: champu-cachos-si-300-ml | D18: Haskell | E18: Shampoo Cachos Sim! 300ml | F18: Champu Cachos Si! 300 ml | G18: Cachos Sim! | H18: Tratamentos Capilares | I18: Tratamientos capilares | J18: Cuidado de cachos | K18: Cuidado de rizos | L18: Shampoo | M18: Champu | N18: 300 ml | O18: 300 | P18: ml | Q18: 62.9 | S18: =IF(ISBLANK(R18),0,IFERROR((Q18-R18)/Q18,0)) | T18: =R18<>"" | U18: =TRUE() | W18: Champu de la linea Cachos Si!, formulado sin sulfatos, petrolatos ni parabenos (tecnica low poo), que limpia suavemente sin remover los aceites naturales del cabello rizado. | Y18: Limpieza suave sin remover aceites naturales | Hidrata el cabello y el cuero cabelludo | Libre de sulfatos, petrolatos y parabenos | AA18: Formula low poo | Libre de sulfatos | AC18: Aplicar sobre el cabello mojado, masajear el cuero cabelludo y enjuagar bien. | AD18: Oleo de Coco | Colageno Vegetal | AE18: Aceite de coco | Colageno vegetal | AH18: shampoo-cachos-sim-haskell-300ml.webp | AJ18: Cabello rizado y ondulado | AK18: https://haskellcosmeticos.com.br/tratamentos-capilares/linha-cachos-sim-haskell/ | AL18: 2026-07-24 | AM18: =IF(ISBLANK(Q18),"",Q18*Parametros_PEN!$B$2) | AN18: =IF(ISBLANK(Q18),"",Q18*Parametros_PEN!$B$2*(1+Parametros_PEN!$B$3)) | AO18: =IF(ISBLANK(R18),"",R18*Parametros_PEN!$B$2) | AP18: =IF(ISBLANK(R18),"",R18*Parametros_PEN!$B$2*(1+Parametros_PEN!$B$3))
A19: HSK-0018 | B19: acondicionador-cachos-si-300-ml | D19: Haskell | E19: Condicionador Cachos Sim! 300ml | F19: Acondicionador Cachos Si! 300 ml | G19: Cachos Sim! | H19: Tratamentos Capilares | I19: Tratamientos capilares | J19: Cuidado de cachos | K19: Cuidado de rizos | L19: Condicionador | M19: Acondicionador | N19: 300 ml | O19: 300 | P19: ml | Q19: 62.9 | S19: =IF(ISBLANK(R19),0,IFERROR((Q19-R19)/Q19,0)) | T19: =R19<>"" | U19: =TRUE() | W19: Acondicionador de la linea Cachos Si! que aporta emoliencia, definicion y brillo, ayuda a controlar el frizz y favorece el cierre de las cuticulas. | Y19: Aporta emoliencia, definicion y brillo | Controla el frizz | Favorece el cierre de las cuticulas | Reduce el volumen | AA19: Emoliente | Definidor de rizos | AC19: Aplicar sobre el cabello lavado, de medios a puntas, dejar actuar y enjuagar. | AD19: Oleo de Coco | Colageno Vegetal | AE19: Aceite de coco | Colageno vegetal | AH19: condicionador-cachos-sim-haskell-300ml.webp | AJ19: Cabello rizado y ondulado | AK19: https://haskellcosmeticos.com.br/tratamentos-capilares/linha-cachos-sim-haskell/ | AL19: 2026-07-24 | AM19: =IF(ISBLANK(Q19),"",Q19*Parametros_PEN!$B$2) | AN19: =IF(ISBLANK(Q19),"",Q19*Parametros_PEN!$B$2*(1+Parametros_PEN!$B$3)) | AO19: =IF(ISBLANK(R19),"",R19*Parametros_PEN!$B$2) | AP19: =IF(ISBLANK(R19),"",R19*Parametros_PEN!$B$2*(1+Parametros_PEN!$B$3))
A20: HSK-0019 | B20: mascarilla-humectante-cachos-si-300-g | D20: Haskell | E20: Mascara Umectante Cachos Sim! 300g | F20: Mascarilla humectante Cachos Si! 300 g | G20: Cachos Sim! | H20: Tratamentos Capilares | I20: Tratamientos capilares | J20: Cuidado de cachos | K20: Cuidado de rizos | L20: Mascara de Tratamento | M20: Mascarilla de tratamiento | N20: 300 g | O20: 300 | P20: g | Q20: 74.9 | S20: =IF(ISBLANK(R20),0,IFERROR((Q20-R20)/Q20,0)) | T20: =R20<>"" | U20: =TRUE() | W20: Mascarilla altamente humectante de la linea Cachos Si!, que devuelve la humedad natural, nutre los rizos mas secos y realza su forma original. | Y20: Alto poder humectante | Nutre los rizos mas secos | Realza la forma original del rizo | AA20: Humectante | Nutritiva | AC20: Aplicar sobre el cabello lavado, distribuir de medios a puntas y dejar actuar antes de enjuagar. | AD20: Oleo de Coco | Colageno Vegetal | AE20: Aceite de coco | Colageno vegetal | AH20: mascara-umectante-cachos-sim-300g.webp | AJ20: Cabello rizado y ondulado, especialmente el mas seco | AK20: https://haskellcosmeticos.com.br/tratamentos-capilares/linha-cachos-sim-haskell/ | AL20: 2026-07-24 | AM20: =IF(ISBLANK(Q20),"",Q20*Parametros_PEN!$B$2) | AN20: =IF(ISBLANK(Q20),"",Q20*Parametros_PEN!$B$2*(1+Parametros_PEN!$B$3)) | AO20: =IF(ISBLANK(R20),"",R20*Parametros_PEN!$B$2) | AP20: =IF(ISBLANK(R20),"",R20*Parametros_PEN!$B$2*(1+Parametros_PEN!$B$3))
A21: HSK-0020 | B21: leave-in-memorizador-de-rizos-cachos-si-300-ml | D21: Haskell | E21: Leave In Memorizador de Cachos Cachos Sim! 300ml | F21: Leave-in memorizador de rizos Cachos Si! 300 ml | G21: Cachos Sim! | H21: Tratamentos Capilares | I21: Tratamientos capilares | J21: Cuidado de cachos | K21: Cuidado de rizos | L21: Finalizador | M21: Leave-in (sin enjuague) | N21: 300 ml | O21: 300 | P21: ml | Q21: 68.9 | S21: =IF(ISBLANK(R21),0,IFERROR((Q21-R21)/Q21,0)) | T21: =R21<>"" | U21: =TRUE() | W21: Leave-in de la linea Cachos Si! que activa y define los rizos, controla el frizz y reactiva la memoria del cabello, con proteccion solar y termica. | Y21: Activa y define los rizos | Controla el frizz | Reactiva la memoria del rizo | Proteccion solar y termica | AA21: Definidor | Con proteccion termica y solar | AC21: Aplicar sobre el cabello humedo, distribuir mechon por mechon y dejar secar al aire o con difusor. | AD21: Oleo de Coco | Colageno Vegetal | AE21: Aceite de coco | Colageno vegetal | AH21: leave-in-memorizador-de-cachos-cachos-sim-haskell-300ml.webp | AJ21: Cabello rizado y ondulado | AK21: https://haskellcosmeticos.com.br/tratamentos-capilares/linha-cachos-sim-haskell/ | AL21: 2026-07-24 | AM21: =IF(ISBLANK(Q21),"",Q21*Parametros_PEN!$B$2) | AN21: =IF(ISBLANK(Q21),"",Q21*Parametros_PEN!$B$2*(1+Parametros_PEN!$B$3)) | AO21: =IF(ISBLANK(R21),"",R21*Parametros_PEN!$B$2) | AP21: =IF(ISBLANK(R21),"",R21*Parametros_PEN!$B$2*(1+Parametros_PEN!$B$3))
A22: HSK-0021 | B22: supermascarilla-acidificante-reductora-de-ph-240-g | D22: Haskell | E22: Supermascara Acidificante Redutor de pH 240g | F22: Supermascarilla acidificante reductora de pH 240 g | G22: Acidificante | H22: Tratamentos Capilares | I22: Tratamientos capilares | J22: Reconstrucao pos-quimica | K22: Reconstruccion post-quimica | L22: Mascara de Tratamento | M22: Mascarilla de tratamiento | N22: 240 g | O22: 240 | P22: g | Q22: 74.9 | S22: =IF(ISBLANK(R22),0,IFERROR((Q22-R22)/Q22,0)) | T22: =R22<>"" | U22: =TRUE() | W22: Mascarilla de tratamiento concentrada de la linea Acidificante, de uso posterior al champu: ayuda a reconstruir el cabello danado por procesos quimicos y a equilibrar el pH de los hilos. | Y22: Tratamiento concentrado | Actua en profundidad sobre la fibra capilar | Refuerza el resultado de la linea | AA22: Tratamiento intensivo | AC22: Aplicar mechon por mechon despues del champu, dejar actuar de 3 a 5 minutos y enjuagar bien. | AD22: Blend de vinagres | Arginina | AE22: Blend de vinagres | Arginina | AH22: supermascara-acidificante-redutor-de-ph-240g.webp | AJ22: Cabello danado por procesos quimicos, con porosidad alta | AK22: https://haskellcosmeticos.com.br/tratamentos-capilares/linha-acidificante-haskell/ | AL22: 2026-07-24 | AM22: =IF(ISBLANK(Q22),"",Q22*Parametros_PEN!$B$2) | AN22: =IF(ISBLANK(Q22),"",Q22*Parametros_PEN!$B$2*(1+Parametros_PEN!$B$3)) | AO22: =IF(ISBLANK(R22),"",R22*Parametros_PEN!$B$2) | AP22: =IF(ISBLANK(R22),"",R22*Parametros_PEN!$B$2*(1+Parametros_PEN!$B$3))
A23: HSK-0022 | B23: champu-acidificante-300-ml | D23: Haskell | E23: Shampoo Acidificante 300ml | F23: Champu acidificante 300 ml | G23: Acidificante | H23: Tratamentos Capilares | I23: Tratamientos capilares | J23: Reconstrucao pos-quimica | K23: Reconstruccion post-quimica | L23: Shampoo | M23: Champu | N23: 300 ml | O23: 300 | P23: ml | Q23: 62.9 | S23: =IF(ISBLANK(R23),0,IFERROR((Q23-R23)/Q23,0)) | T23: =R23<>"" | U23: =TRUE() | W23: Champu de limpieza suave de la linea Acidificante, que prepara el cabello para el tratamiento: ayuda a reconstruir el cabello danado por procesos quimicos y a equilibrar el pH de los hilos. | Y23: Limpieza suave sin resecar | Prepara el cabello para el resto de la rutina | Respeta el equilibrio del cuero cabelludo | AA23: Limpiador suave | AC23: Aplicar sobre el cabello mojado, masajear el cuero cabelludo con movimientos suaves y enjuagar bien. | AD23: Blend de vinagres | Arginina | AE23: Blend de vinagres | Arginina | AH23: shampoo-acidificante-300ml.webp | AJ23: Cabello danado por procesos quimicos, con porosidad alta | AK23: https://haskellcosmeticos.com.br/tratamentos-capilares/linha-acidificante-haskell/ | AL23: 2026-07-24 | AM23: =IF(ISBLANK(Q23),"",Q23*Parametros_PEN!$B$2) | AN23: =IF(ISBLANK(Q23),"",Q23*Parametros_PEN!$B$2*(1+Parametros_PEN!$B$3)) | AO23: =IF(ISBLANK(R23),"",R23*Parametros_PEN!$B$2) | AP23: =IF(ISBLANK(R23),"",R23*Parametros_PEN!$B$2*(1+Parametros_PEN!$B$3))
A24: HSK-0023 | B24: fluido-reconstructor-acidificante-200-ml | D24: Haskell | E24: Fluido Reconstrutor Acidificante 200ml | F24: Fluido reconstructor acidificante 200 ml | G24: Acidificante | H24: Tratamentos Capilares | I24: Tratamientos capilares | J24: Reconstrucao pos-quimica | K24: Reconstruccion post-quimica | L24: Fluido | M24: Fluido finalizador | N24: 200 ml | O24: 200 | P24: ml | Q24: 59.9 | S24: =IF(ISBLANK(R24),0,IFERROR((Q24-R24)/Q24,0)) | T24: =R24<>"" | U24: =TRUE() | W24: Fluido finalizador sin enjuague de la linea Acidificante: ayuda a reconstruir el cabello danado por procesos quimicos y a equilibrar el pH de los hilos. | Y24: Finalizador sin enjuague | Facilita el peinado | Protege del calor y de agresiones externas | AA24: Finalizador | AC24: Aplicar sobre el cabello limpio y humedo, distribuir en todo el largo y finalizar como se prefiera. | AD24: Blend de vinagres | Arginina | AE24: Blend de vinagres | Arginina | AH24: fluido-reconstrutor-acidificante-200ml.webp | AJ24: Cabello danado por procesos quimicos, con porosidad alta | AK24: https://haskellcosmeticos.com.br/tratamentos-capilares/linha-acidificante-haskell/ | AL24: 2026-07-24 | AM24: =IF(ISBLANK(Q24),"",Q24*Parametros_PEN!$B$2) | AN24: =IF(ISBLANK(Q24),"",Q24*Parametros_PEN!$B$2*(1+Parametros_PEN!$B$3)) | AO24: =IF(ISBLANK(R24),"",R24*Parametros_PEN!$B$2) | AP24: =IF(ISBLANK(R24),"",R24*Parametros_PEN!$B$2*(1+Parametros_PEN!$B$3))
A25: HSK-0024 | B25: supermascarilla-acidificante-matizadora-240-g | D25: Haskell | E25: Supermascara Acidificante Matizadora 240g | F25: Supermascarilla acidificante matizadora 240 g | G25: Acidificante Matizadora | H25: Tratamentos Capilares | I25: Tratamientos capilares | J25: Matizacao acida | K25: Matizacion acida para cabello rubio o canoso | L25: Mascara de Tratamento | M25: Mascarilla de tratamiento | N25: 240 g | O25: 240 | P25: g | Q25: 74.9 | S25: =IF(ISBLANK(R25),0,IFERROR((Q25-R25)/Q25,0)) | T25: =R25<>"" | U25: =TRUE() | W25: Mascarilla de tratamiento concentrada de la linea Acidificante Matizadora, de uso posterior al champu: neutraliza el tono amarillento y equilibra el pH del cabello rubio, decolorado o canoso. | Y25: Tratamiento concentrado | Actua en profundidad sobre la fibra capilar | Refuerza el resultado de la linea | AA25: Tratamiento intensivo | AC25: Aplicar mechon por mechon despues del champu, dejar actuar de 3 a 5 minutos y enjuagar bien. | AD25: Blend de vinagres | Arginina | AE25: Blend de vinagres | Arginina | AH25: Supermascarilla acidificante matizadora 240 g.webp | AJ25: Cabello rubio, decolorado o canoso con tono amarillento | AK25: https://haskellcosmeticos.com.br/tratamentos-capilares/acidificante-matizadora/ | AL25: 2026-07-24 | AM25: =IF(ISBLANK(Q25),"",Q25*Parametros_PEN!$B$2) | AN25: =IF(ISBLANK(Q25),"",Q25*Parametros_PEN!$B$2*(1+Parametros_PEN!$B$3)) | AO25: =IF(ISBLANK(R25),"",R25*Parametros_PEN!$B$2) | AP25: =IF(ISBLANK(R25),"",R25*Parametros_PEN!$B$2*(1+Parametros_PEN!$B$3))
A26: HSK-0025 | B26: champu-acidificante-matizador-300-ml | D26: Haskell | E26: Shampoo Acidificante Matizador 300ml | F26: Champu acidificante matizador 300 ml | G26: Acidificante Matizadora | H26: Tratamentos Capilares | I26: Tratamientos capilares | J26: Matizacao acida | K26: Matizacion acida para cabello rubio o canoso | L26: Shampoo | M26: Champu | N26: 300 ml | O26: 300 | P26: ml | Q26: 62.9 | S26: =IF(ISBLANK(R26),0,IFERROR((Q26-R26)/Q26,0)) | T26: =R26<>"" | U26: =TRUE() | W26: Champu de limpieza suave de la linea Acidificante Matizadora, que prepara el cabello para el tratamiento: neutraliza el tono amarillento y equilibra el pH del cabello rubio, decolorado o canoso. | Y26: Limpieza suave sin resecar | Prepara el cabello para el resto de la rutina | Respeta el equilibrio del cuero cabelludo | AA26: Limpiador suave | AC26: Aplicar sobre el cabello mojado, masajear el cuero cabelludo con movimientos suaves y enjuagar bien. | AD26: Blend de vinagres | Arginina | AE26: Blend de vinagres | Arginina | AH26: shampoo-acidificante-matizador-300ml.webp | AI26: shampoo-acidificante-matizador-300ml_02.webp | AJ26: Cabello rubio, decolorado o canoso con tono amarillento | AK26: https://haskellcosmeticos.com.br/tratamentos-capilares/acidificante-matizadora/ | AL26: 2026-07-24 | AM26: =IF(ISBLANK(Q26),"",Q26*Parametros_PEN!$B$2) | AN26: =IF(ISBLANK(Q26),"",Q26*Parametros_PEN!$B$2*(1+Parametros_PEN!$B$3)) | AO26: =IF(ISBLANK(R26),"",R26*Parametros_PEN!$B$2) | AP26: =IF(ISBLANK(R26),"",R26*Parametros_PEN!$B$2*(1+Parametros_PEN!$B$3))
A27: HSK-0026 | B27: balsamo-cicatrizante-acidificante-matizador-100-ml | D27: Haskell | E27: Balm Cicatrizante Acidificante Matizador 100ml | F27: Balsamo cicatrizante acidificante matizador 100 ml | G27: Acidificante Matizadora | H27: Tratamentos Capilares | I27: Tratamientos capilares | J27: Matizacao acida | K27: Matizacion acida para cabello rubio o canoso | L27: Balm | M27: Balsamo | N27: 100 ml | O27: 100 | P27: ml | Q27: 95.9 | S27: =IF(ISBLANK(R27),0,IFERROR((Q27-R27)/Q27,0)) | T27: =R27<>"" | U27: =TRUE() | W27: Balsamo de accion reparadora de la linea Acidificante Matizadora: neutraliza el tono amarillento y equilibra el pH del cabello rubio, decolorado o canoso. | Y27: Accion reparadora localizada | Complementa el tratamiento de la linea | AA27: Balsamo tratante | AC27: Aplicar sobre el cabello segun las indicaciones del envase, como parte de la rutina de la linea. | AD27: Blend de vinagres | Arginina | AE27: Blend de vinagres | Arginina | AH27: balm-cicatrizante-acidificante-matizador-100ml.webp | AI27: balm-cicatrizante-acidificante-matizador-100ml_02.webp | AJ27: Cabello rubio, decolorado o canoso con tono amarillento | AK27: https://haskellcosmeticos.com.br/tratamentos-capilares/acidificante-matizadora/ | AL27: 2026-07-24 | AM27: =IF(ISBLANK(Q27),"",Q27*Parametros_PEN!$B$2) | AN27: =IF(ISBLANK(Q27),"",Q27*Parametros_PEN!$B$2*(1+Parametros_PEN!$B$3)) | AO27: =IF(ISBLANK(R27),"",R27*Parametros_PEN!$B$2) | AP27: =IF(ISBLANK(R27),"",R27*Parametros_PEN!$B$2*(1+Parametros_PEN!$B$3))
A28: HSK-0027 | B28: champu-amatista-desamarilladora-300-ml | D28: Haskell | E28: Shampoo Ametista Desamareladora 300ml | F28: Champu amatista desamarilladora 300 ml | G28: Ametista Desamareladora | H28: Tratamentos Capilares | I28: Tratamientos capilares | J28: Desamarelamento gradual | K28: Desamarillamiento gradual | L28: Shampoo | M28: Champu | N28: 300 ml | O28: 300 | P28: ml | Q28: 62.9 | S28: =IF(ISBLANK(R28),0,IFERROR((Q28-R28)/Q28,0)) | T28: =R28<>"" | U28: =TRUE() | W28: Champu de limpieza suave de la linea Ametista Desamareladora, que prepara el cabello para el tratamiento: neutraliza de forma gradual los reflejos amarillentos y aporta brillo. | Y28: Limpieza suave sin resecar | Prepara el cabello para el resto de la rutina | Respeta el equilibrio del cuero cabelludo | AA28: Limpiador suave | AC28: Aplicar sobre el cabello mojado, masajear el cuero cabelludo con movimientos suaves y enjuagar bien. | AD28: Ametista (mineral) | Blend de aminoacidos | AE28: Amatista (mineral) | Blend de aminoacidos | AH28: shampoo-ametista-desamareladora-300ml.webp | AJ28: Cabello rubio, decolorado, canoso o cabello oscuro que necesita mas brillo | AK28: https://haskellcosmeticos.com.br/tratamentos-capilares/linha-ametista-haskell/ | AL28: 2026-07-24 | AM28: =IF(ISBLANK(Q28),"",Q28*Parametros_PEN!$B$2) | AN28: =IF(ISBLANK(Q28),"",Q28*Parametros_PEN!$B$2*(1+Parametros_PEN!$B$3)) | AO28: =IF(ISBLANK(R28),"",R28*Parametros_PEN!$B$2) | AP28: =IF(ISBLANK(R28),"",R28*Parametros_PEN!$B$2*(1+Parametros_PEN!$B$3))
A29: HSK-0028 | B29: acondicionador-amatista-desamarilladora-300-ml | D29: Haskell | E29: Condicionador Ametista Desamareladora 300ml | F29: Acondicionador amatista desamarilladora 300 ml | G29: Ametista Desamareladora | H29: Tratamentos Capilares | I29: Tratamientos capilares | J29: Desamarelamento gradual | K29: Desamarillamiento gradual | L29: Condicionador | M29: Acondicionador | N29: 300 ml | O29: 300 | P29: ml | Q29: 62.9 | S29: =IF(ISBLANK(R29),0,IFERROR((Q29-R29)/Q29,0)) | T29: =R29<>"" | U29: =TRUE() | W29: Acondicionador de la linea Ametista Desamareladora que facilita el desenredado y sella la cuticula: neutraliza de forma gradual los reflejos amarillentos y aporta brillo. | Y29: Facilita el desenredado | Sella la cuticula | Aporta suavidad y brillo | AA29: Acondicionador | AC29: Aplicar en el largo y las puntas del cabello despues del champu, dejar actuar unos minutos y enjuagar. | AD29: Ametista (mineral) | Blend de aminoacidos | AE29: Amatista (mineral) | Blend de aminoacidos | AH29: condicionador-ametista-desamareladora-300ml.webp | AJ29: Cabello rubio, decolorado, canoso o cabello oscuro que necesita mas brillo | AK29: https://haskellcosmeticos.com.br/tratamentos-capilares/linha-ametista-haskell/ | AL29: 2026-07-24 | AM29: =IF(ISBLANK(Q29),"",Q29*Parametros_PEN!$B$2) | AN29: =IF(ISBLANK(Q29),"",Q29*Parametros_PEN!$B$2*(1+Parametros_PEN!$B$3)) | AO29: =IF(ISBLANK(R29),"",R29*Parametros_PEN!$B$2) | AP29: =IF(ISBLANK(R29),"",R29*Parametros_PEN!$B$2*(1+Parametros_PEN!$B$3))
A30: HSK-0029 | B30: mascarilla-de-tratamiento-amatista-desamarilladora-300-g | D30: Haskell | E30: Mascara de Tratamento Ametista Desamareladora 300g | F30: Mascarilla de tratamiento amatista desamarilladora 300 g | G30: Ametista Desamareladora | H30: Tratamentos Capilares | I30: Tratamientos capilares | J30: Desamarelamento gradual | K30: Desamarillamiento gradual | L30: Mascara de Tratamento | M30: Mascarilla de tratamiento | N30: 300 g | O30: 300 | P30: g | Q30: 74.9 | S30: =IF(ISBLANK(R30),0,IFERROR((Q30-R30)/Q30,0)) | T30: =R30<>"" | U30: =TRUE() | W30: Mascarilla de tratamiento concentrada de la linea Ametista Desamareladora, de uso posterior al champu: neutraliza de forma gradual los reflejos amarillentos y aporta brillo. | Y30: Tratamiento concentrado | Actua en profundidad sobre la fibra capilar | Refuerza el resultado de la linea | AA30: Tratamiento intensivo | AC30: Aplicar mechon por mechon despues del champu, dejar actuar de 3 a 5 minutos y enjuagar bien. | AD30: Ametista (mineral) | Blend de aminoacidos | AE30: Amatista (mineral) | Blend de aminoacidos | AH30: mascara-de-tratamento-ametista-desamareladora-300g.webp | AJ30: Cabello rubio, decolorado, canoso o cabello oscuro que necesita mas brillo | AK30: https://haskellcosmeticos.com.br/tratamentos-capilares/linha-ametista-haskell/ | AL30: 2026-07-24 | AM30: =IF(ISBLANK(Q30),"",Q30*Parametros_PEN!$B$2) | AN30: =IF(ISBLANK(Q30),"",Q30*Parametros_PEN!$B$2*(1+Parametros_PEN!$B$3)) | AO30: =IF(ISBLANK(R30),"",R30*Parametros_PEN!$B$2) | AP30: =IF(ISBLANK(R30),"",R30*Parametros_PEN!$B$2*(1+Parametros_PEN!$B$3))
A31: HSK-0030 | B31: fluido-iluminador-amatista-desamarilladora-120-ml | D31: Haskell | E31: Fluido Iluminador Ametista Desamareladora 120ml | F31: Fluido iluminador amatista desamarilladora 120 ml | G31: Ametista Desamareladora | H31: Tratamentos Capilares | I31: Tratamientos capilares | J31: Desamarelamento gradual | K31: Desamarillamiento gradual | L31: Fluido | M31: Fluido finalizador | N31: 120 ml | O31: 120 | P31: ml | Q31: 48.9 | S31: =IF(ISBLANK(R31),0,IFERROR((Q31-R31)/Q31,0)) | T31: =R31<>"" | U31: =TRUE() | W31: Fluido finalizador sin enjuague de la linea Ametista Desamareladora: neutraliza de forma gradual los reflejos amarillentos y aporta brillo. | Y31: Finalizador sin enjuague | Facilita el peinado | Protege del calor y de agresiones externas | AA31: Finalizador | AC31: Aplicar sobre el cabello limpio y humedo, distribuir en todo el largo y finalizar como se prefiera. | AD31: Ametista (mineral) | Blend de aminoacidos | AE31: Amatista (mineral) | Blend de aminoacidos | AH31: fluido-iluminador-ametista-desamareladora-120ml.webp | AJ31: Cabello rubio, decolorado, canoso o cabello oscuro que necesita mas brillo | AK31: https://haskellcosmeticos.com.br/tratamentos-capilares/linha-ametista-haskell/ | AL31: 2026-07-24 | AM31: =IF(ISBLANK(Q31),"",Q31*Parametros_PEN!$B$2) | AN31: =IF(ISBLANK(Q31),"",Q31*Parametros_PEN!$B$2*(1+Parametros_PEN!$B$3)) | AO31: =IF(ISBLANK(R31),"",R31*Parametros_PEN!$B$2) | AP31: =IF(ISBLANK(R31),"",R31*Parametros_PEN!$B$2*(1+Parametros_PEN!$B$3))
A32: HSK-0031 | B32: champu-bananeira-posquimica-300-ml | D32: Haskell | E32: Shampoo Bananeira Pos-Quimica 300ml | F32: Champu Bananeira Posquimica 300 ml | G32: Bananeira Pos-Quimica | H32: Tratamentos Capilares | I32: Tratamientos capilares | J32: Reposicao de massa pos-quimica | K32: Reposicion de masa capilar post-quimica | L32: Shampoo | M32: Champu | N32: 300 ml | O32: 300 | P32: ml | Q32: 62.9 | S32: =IF(ISBLANK(R32),0,IFERROR((Q32-R32)/Q32,0)) | T32: =R32<>"" | U32: =TRUE() | W32: Champu de limpieza suave de la linea Bananeira Pos-Quimica, que prepara el cabello para el tratamiento: repone la masa capilar perdida en procesos quimicos y ayuda a reducir la quiebre. | Y32: Limpieza suave sin resecar | Prepara el cabello para el resto de la rutina | Respeta el equilibrio del cuero cabelludo | AA32: Limpiador suave | AC32: Aplicar sobre el cabello mojado, masajear el cuero cabelludo con movimientos suaves y enjuagar bien. | AD32: Nutrientes de banana | Oleo de pequi | AE32: Nutrientes de platano (banana) | Aceite de pequi | AH32: shampoo-bananeira-pos-quimica-300ml.webp | AJ32: Cabello danado por alisados, tinturas o decoloracion | AK32: https://haskellcosmeticos.com.br/tratamentos-capilares/linha-bananeira-haskell/ | AL32: 2026-07-24 | AM32: =IF(ISBLANK(Q32),"",Q32*Parametros_PEN!$B$2) | AN32: =IF(ISBLANK(Q32),"",Q32*Parametros_PEN!$B$2*(1+Parametros_PEN!$B$3)) | AO32: =IF(ISBLANK(R32),"",R32*Parametros_PEN!$B$2) | AP32: =IF(ISBLANK(R32),"",R32*Parametros_PEN!$B$2*(1+Parametros_PEN!$B$3))
A33: HSK-0032 | B33: champu-bananeira-posquimica-500-ml | D33: Haskell | E33: Shampoo Bananeira Pos Quimica 500ml | F33: Champu Bananeira Posquimica 500 ml | G33: Bananeira Pos-Quimica | H33: Tratamentos Capilares | I33: Tratamientos capilares | J33: Reposicao de massa pos-quimica | K33: Reposicion de masa capilar post-quimica | L33: Shampoo | M33: Champu | N33: 500 ml | O33: 500 | P33: ml | Q33: 84.9 | S33: =IF(ISBLANK(R33),0,IFERROR((Q33-R33)/Q33,0)) | T33: =R33<>"" | U33: =TRUE() | W33: Champu de limpieza suave de la linea Bananeira Pos-Quimica, que prepara el cabello para el tratamiento: repone la masa capilar perdida en procesos quimicos y ayuda a reducir la quiebre. | Y33: Limpieza suave sin resecar | Prepara el cabello para el resto de la rutina | Respeta el equilibrio del cuero cabelludo | AA33: Limpiador suave | AC33: Aplicar sobre el cabello mojado, masajear el cuero cabelludo con movimientos suaves y enjuagar bien. | AD33: Nutrientes de banana | Oleo de pequi | AE33: Nutrientes de platano (banana) | Aceite de pequi | AH33: shampoo-bananeira-pos-quimica-500ml.webp | AJ33: Cabello danado por alisados, tinturas o decoloracion | AK33: https://haskellcosmeticos.com.br/tratamentos-capilares/linha-bananeira-haskell/ | AL33: 2026-07-24 | AM33: =IF(ISBLANK(Q33),"",Q33*Parametros_PEN!$B$2) | AN33: =IF(ISBLANK(Q33),"",Q33*Parametros_PEN!$B$2*(1+Parametros_PEN!$B$3)) | AO33: =IF(ISBLANK(R33),"",R33*Parametros_PEN!$B$2) | AP33: =IF(ISBLANK(R33),"",R33*Parametros_PEN!$B$2*(1+Parametros_PEN!$B$3))
A34: HSK-0033 | B34: acondicionador-bananeira-posquimica-300-ml | D34: Haskell | E34: Condicionador Bananeira Pos-Quimica 300ml | F34: Acondicionador Bananeira Posquimica 300 ml | G34: Bananeira Pos-Quimica | H34: Tratamentos Capilares | I34: Tratamientos capilares | J34: Reposicao de massa pos-quimica | K34: Reposicion de masa capilar post-quimica | L34: Condicionador | M34: Acondicionador | N34: 300 ml | O34: 300 | P34: ml | Q34: 62.9 | S34: =IF(ISBLANK(R34),0,IFERROR((Q34-R34)/Q34,0)) | T34: =R34<>"" | U34: =TRUE() | W34: Acondicionador de la linea Bananeira Pos-Quimica que facilita el desenredado y sella la cuticula: repone la masa capilar perdida en procesos quimicos y ayuda a reducir la quiebre. | Y34: Facilita el desenredado | Sella la cuticula | Aporta suavidad y brillo | AA34: Acondicionador | AC34: Aplicar en el largo y las puntas del cabello despues del champu, dejar actuar unos minutos y enjuagar. | AD34: Nutrientes de banana | Oleo de pequi | AE34: Nutrientes de platano (banana) | Aceite de pequi | AH34: condicionador-bananeira-pos-quimica-300ml.webp | AJ34: Cabello danado por alisados, tinturas o decoloracion | AK34: https://haskellcosmeticos.com.br/tratamentos-capilares/linha-bananeira-haskell/ | AL34: 2026-07-24 | AM34: =IF(ISBLANK(Q34),"",Q34*Parametros_PEN!$B$2) | AN34: =IF(ISBLANK(Q34),"",Q34*Parametros_PEN!$B$2*(1+Parametros_PEN!$B$3)) | AO34: =IF(ISBLANK(R34),"",R34*Parametros_PEN!$B$2) | AP34: =IF(ISBLANK(R34),"",R34*Parametros_PEN!$B$2*(1+Parametros_PEN!$B$3))
A35: HSK-0034 | B35: acondicionador-bananeira-posquimica-500-ml | D35: Haskell | E35: Condicionador Bananeira Pos Quimica 500ml | F35: Acondicionador Bananeira Posquimica 500 ml | G35: Bananeira Pos-Quimica | H35: Tratamentos Capilares | I35: Tratamientos capilares | J35: Reposicao de massa pos-quimica | K35: Reposicion de masa capilar post-quimica | L35: Condicionador | M35: Acondicionador | N35: 500 ml | O35: 500 | P35: ml | Q35: 84.9 | S35: =IF(ISBLANK(R35),0,IFERROR((Q35-R35)/Q35,0)) | T35: =R35<>"" | U35: =TRUE() | W35: Acondicionador de la linea Bananeira Pos-Quimica que facilita el desenredado y sella la cuticula: repone la masa capilar perdida en procesos quimicos y ayuda a reducir la quiebre. | Y35: Facilita el desenredado | Sella la cuticula | Aporta suavidad y brillo | AA35: Acondicionador | AC35: Aplicar en el largo y las puntas del cabello despues del champu, dejar actuar unos minutos y enjuagar. | AD35: Nutrientes de banana | Oleo de pequi | AE35: Nutrientes de platano (banana) | Aceite de pequi | AH35: condicionador-bananeira-pos-quimica-500ml.webp | AJ35: Cabello danado por alisados, tinturas o decoloracion | AK35: https://haskellcosmeticos.com.br/tratamentos-capilares/linha-bananeira-haskell/ | AL35: 2026-07-24 | AM35: =IF(ISBLANK(Q35),"",Q35*Parametros_PEN!$B$2) | AN35: =IF(ISBLANK(Q35),"",Q35*Parametros_PEN!$B$2*(1+Parametros_PEN!$B$3)) | AO35: =IF(ISBLANK(R35),"",R35*Parametros_PEN!$B$2) | AP35: =IF(ISBLANK(R35),"",R35*Parametros_PEN!$B$2*(1+Parametros_PEN!$B$3))
A36: HSK-0035 | B36: mascarilla-de-tratamiento-bananeira-posquimica-300-g | D36: Haskell | E36: Mascara de Tratamento Bananeira Pos-Quimica 300g | F36: Mascarilla de tratamiento Bananeira Posquimica 300 g | G36: Bananeira Pos-Quimica | H36: Tratamentos Capilares | I36: Tratamientos capilares | J36: Reposicao de massa pos-quimica | K36: Reposicion de masa capilar post-quimica | L36: Mascara de Tratamento | M36: Mascarilla de tratamiento | N36: 300 g | O36: 300 | P36: g | Q36: 74.9 | S36: =IF(ISBLANK(R36),0,IFERROR((Q36-R36)/Q36,0)) | T36: =R36<>"" | U36: =TRUE() | W36: Mascarilla de tratamiento concentrada de la linea Bananeira Pos-Quimica, de uso posterior al champu: repone la masa capilar perdida en procesos quimicos y ayuda a reducir la quiebre. | Y36: Tratamiento concentrado | Actua en profundidad sobre la fibra capilar | Refuerza el resultado de la linea | AA36: Tratamiento intensivo | AC36: Aplicar mechon por mechon despues del champu, dejar actuar de 3 a 5 minutos y enjuagar bien. | AD36: Nutrientes de banana | Oleo de pequi | AE36: Nutrientes de platano (banana) | Aceite de pequi | AH36: mascara-de-tratamento-bananeira-pos-quimica-300g.webp | AJ36: Cabello danado por alisados, tinturas o decoloracion | AK36: https://haskellcosmeticos.com.br/tratamentos-capilares/linha-bananeira-haskell/ | AL36: 2026-07-24 | AM36: =IF(ISBLANK(Q36),"",Q36*Parametros_PEN!$B$2) | AN36: =IF(ISBLANK(Q36),"",Q36*Parametros_PEN!$B$2*(1+Parametros_PEN!$B$3)) | AO36: =IF(ISBLANK(R36),"",R36*Parametros_PEN!$B$2) | AP36: =IF(ISBLANK(R36),"",R36*Parametros_PEN!$B$2*(1+Parametros_PEN!$B$3))
A37: HSK-0036 | B37: mascarilla-de-tratamiento-bananeira-posquimica-500-g | D37: Haskell | E37: Mascara de Tratamento Bananeira Pos-Quimica 500g | F37: Mascarilla de tratamiento Bananeira Posquimica 500 g | G37: Bananeira Pos-Quimica | H37: Tratamentos Capilares | I37: Tratamientos capilares | J37: Reposicao de massa pos-quimica | K37: Reposicion de masa capilar post-quimica | L37: Mascara de Tratamento | M37: Mascarilla de tratamiento | N37: 500 g | O37: 500 | P37: g | Q37: 89.9 | S37: =IF(ISBLANK(R37),0,IFERROR((Q37-R37)/Q37,0)) | T37: =R37<>"" | U37: =TRUE() | W37: Mascarilla de tratamiento concentrada de la linea Bananeira Pos-Quimica, de uso posterior al champu: repone la masa capilar perdida en procesos quimicos y ayuda a reducir la quiebre. | Y37: Tratamiento concentrado | Actua en profundidad sobre la fibra capilar | Refuerza el resultado de la linea | AA37: Tratamiento intensivo | AC37: Aplicar mechon por mechon despues del champu, dejar actuar de 3 a 5 minutos y enjuagar bien. | AD37: Nutrientes de banana | Oleo de pequi | AE37: Nutrientes de platano (banana) | Aceite de pequi | AH37: mascara-de-tratamento-bananeira-pos-quimica-500g.webp | AJ37: Cabello danado por alisados, tinturas o decoloracion | AK37: https://haskellcosmeticos.com.br/tratamentos-capilares/linha-bananeira-haskell/ | AL37: 2026-07-24 | AM37: =IF(ISBLANK(Q37),"",Q37*Parametros_PEN!$B$2) | AN37: =IF(ISBLANK(Q37),"",Q37*Parametros_PEN!$B$2*(1+Parametros_PEN!$B$3)) | AO37: =IF(ISBLANK(R37),"",R37*Parametros_PEN!$B$2) | AP37: =IF(ISBLANK(R37),"",R37*Parametros_PEN!$B$2*(1+Parametros_PEN!$B$3))
A38: HSK-0037 | B38: fluido-obligatorio-bananeira-posquimica-120-ml | D38: Haskell | E38: Fluido Obrigatorio Bananeira Pos-Quimica 120ml | F38: Fluido obligatorio Bananeira Posquimica 120 ml | G38: Bananeira Pos-Quimica | H38: Tratamentos Capilares | I38: Tratamientos capilares | J38: Reposicao de massa pos-quimica | K38: Reposicion de masa capilar post-quimica | L38: Fluido | M38: Fluido finalizador | N38: 120 ml | O38: 120 | P38: ml | Q38: 48.9 | S38: =IF(ISBLANK(R38),0,IFERROR((Q38-R38)/Q38,0)) | T38: =R38<>"" | U38: =TRUE() | W38: Fluido finalizador sin enjuague de la linea Bananeira Pos-Quimica: repone la masa capilar perdida en procesos quimicos y ayuda a reducir la quiebre. | Y38: Finalizador sin enjuague | Facilita el peinado | Protege del calor y de agresiones externas | AA38: Finalizador | AC38: Aplicar sobre el cabello limpio y humedo, distribuir en todo el largo y finalizar como se prefiera. | AD38: Nutrientes de banana | Oleo de pequi | AE38: Nutrientes de platano (banana) | Aceite de pequi | AH38: fluido-obrigatorio-bananeira-pos-quimica-120ml.webp | AJ38: Cabello danado por alisados, tinturas o decoloracion | AK38: https://haskellcosmeticos.com.br/tratamentos-capilares/linha-bananeira-haskell/ | AL38: 2026-07-24 | AM38: =IF(ISBLANK(Q38),"",Q38*Parametros_PEN!$B$2) | AN38: =IF(ISBLANK(Q38),"",Q38*Parametros_PEN!$B$2*(1+Parametros_PEN!$B$3)) | AO38: =IF(ISBLANK(R38),"",R38*Parametros_PEN!$B$2) | AP38: =IF(ISBLANK(R38),"",R38*Parametros_PEN!$B$2*(1+Parametros_PEN!$B$3))
A39: HSK-0038 | B39: nectavita-bananeira-posquimica-35-ml | D39: Haskell | E39: Nectavita Bananeira Pos-Quimica 35ml | F39: Nectavita Bananeira Posquimica 35 ml | G39: Bananeira Pos-Quimica | H39: Tratamentos Capilares | I39: Tratamientos capilares | J39: Reposicao de massa pos-quimica | K39: Reposicion de masa capilar post-quimica | L39: Nectavita | M39: Potenciador pre-champu | N39: 35 ml | O39: 35 | P39: ml | Q39: 25.9 | S39: =IF(ISBLANK(R39),0,IFERROR((Q39-R39)/Q39,0)) | T39: =R39<>"" | U39: =TRUE() | W39: Potenciador pre-champu (nectavita) de la linea Bananeira Pos-Quimica, para usar antes del lavado: repone la masa capilar perdida en procesos quimicos y ayuda a reducir la quiebre. | Y39: Prepara el cuero cabelludo antes del champu | Potencia el efecto del tratamiento | AA39: Pre-champu | AC39: Aplicar sobre el cuero cabelludo antes del champu, masajear y proceder con el lavado habitual. | AD39: Nutrientes de banana | Oleo de pequi | AE39: Nutrientes de platano (banana) | Aceite de pequi | AH39: nectavita-bananeira-pos-quimica-35ml.webp | AJ39: Cabello danado por alisados, tinturas o decoloracion | AK39: https://haskellcosmeticos.com.br/tratamentos-capilares/linha-bananeira-haskell/ | AL39: 2026-07-24 | AM39: =IF(ISBLANK(Q39),"",Q39*Parametros_PEN!$B$2) | AN39: =IF(ISBLANK(Q39),"",Q39*Parametros_PEN!$B$2*(1+Parametros_PEN!$B$3)) | AO39: =IF(ISBLANK(R39),"",R39*Parametros_PEN!$B$2) | AP39: =IF(ISBLANK(R39),"",R39*Parametros_PEN!$B$2*(1+Parametros_PEN!$B$3))
... A46: HSK-0045 | B46: fluido-hidratante-cavalo-forte-hidra-120-ml | D46: Haskell | E46: Fluido Hidratante Cavalo Forte Hidra 120ml | F46: Fluido hidratante Cavalo Forte Hidra 120 ml | G46: Cavalo Forte Hidra | H46: Tratamentos Capilares | I46: Tratamientos capilares | J46: Hidratacao profunda | K46: Hidratacion profunda | L46: Fluido | M46: Fluido finalizador | N46: 120 ml | O46: 120 | P46: ml | Q46: 48.9 | S46: =IF(ISBLANK(R46),0,IFERROR((Q46-R46)/Q46,0)) | T46: =R46<>"" | U46: =TRUE() | W46: Fluido finalizador sin enjuague de la linea Cavalo Forte Hidra: aporta hidratacion profunda y protege el cabello frente a agresiones externas. | Y46: Finalizador sin enjuague | Facilita el peinado | Protege del calor y de agresiones externas | AA46: Finalizador | AC46: Aplicar sobre el cabello limpio y humedo, distribuir en todo el largo y finalizar como se prefiera. | AD46: Acido hialuronico | Oleo de rosa mosqueta | Vitamina B3 | AE46: Acido hialuronico | Aceite de rosa mosqueta | Vitamina B3 | AH46: fluido-hidratante-cavalo-forte-hidra-120ml.webp | AJ46: Todo tipo de cabello, especialmente cabello reseco | AK46: https://haskellcosmeticos.com.br/tratamentos-capilares/cavalo-forte-hidra/ | AL46: 2026-07-24 | AM46: =IF(ISBLANK(Q46),"",Q46*Parametros_PEN!$B$2) | AN46: =IF(ISBLANK(Q46),"",Q46*Parametros_PEN!$B$2*(1+Parametros_PEN!$B$3)) | AO46: =IF(ISBLANK(R46),"",R46*Parametros_PEN!$B$2) | AP46: =IF(ISBLANK(R46),"",R46*Parametros_PEN!$B$2*(1+Parametros_PEN!$B$3))
...

Sheet Parametros_PEN
A1: Parametro | B1: Valor
A2: Tipo de cambio (soles PEN por 1 real BRL) | B2: 0.67
A3: Margen sobre el precio convertido para fijar el PVP en Peru | B3: 0.25
A5: Formula aplicada
A6: precio_pen = precio_brl x tipo_cambio
A7: pvp_peru_pen = precio_pen x (1 + margen)
A9: Nota
A10: Celdas B2 y B3 son los unicos valores editables. El resto del catalogo (hoja Productos) usa formulas que apuntan a estas dos celdas: si se actualiza el tipo de cambio o el margen aca, todos los precios en soles y el PVP se recalculan automaticamente en toda la hoja Productos.

Sheet Categorias_Lineas
A1: categoria_original_pt | B1: categoria_es | C1: linea | D1: subcategoria_original_pt | E1: subcategoria_es | F1: cantidad_productos_en_muestra
A2: Tratamentos Capilares | B2: Tratamientos capilares | C2: Acidificante | D2: Reconstrucao pos-quimica | E2: Reconstruccion post-quimica | F2: 3
A3: Tratamentos Capilares | B3: Tratamientos capilares | C3: Acidificante Matizadora | D3: Matizacao acida | E3: Matizacion acida para cabello rubio o canoso | F3: 3
A4: Tratamentos Capilares | B4: Tratamientos capilares | C4: Ametista Desamareladora | D4: Desamarelamento gradual | E4: Desamarillamiento gradual | F4: 4
A5: Tratamentos Capilares | B5: Tratamientos capilares | C5: Bananeira Pos-Quimica | D5: Reposicao de massa pos-quimica | E5: Reposicion de masa capilar post-quimica | F5: 8
A6: Tratamentos Capilares | B6: Tratamientos capilares | C6: Bendito Loiro | D6: Cabelos descoloridos | E6: Cabello decolorado | F6: 6
A7: Tratamentos Capilares | B7: Tratamientos capilares | C7: Cachos Sim! | D7: Cuidado de cachos | E7: Cuidado de rizos | F7: 4
A8: Tratamentos Capilares | B8: Tratamientos capilares | C8: Cavalo Forte | D8: Fortalecimento | E8: Fortalecimiento capilar | F8: 1
